2017-03-24 17:51:07,101 - INFO - my_logging logger is started. Console : DEBUG. File (.log) : INFO
2017-03-24 17:51:09,223 - INFO - Lecture des données
2017-03-24 17:51:09,878 - INFO - 21971 mesures trouvées.
2017-03-24 17:51:09,880 - INFO - Correction des moyennes des vitesses angulaires : x:-667, y:-21, z:-230
2017-03-24 17:51:09,930 - INFO - Scan du repertoir images : Q:\Frederic\Gyro ...
2017-03-24 17:51:57,322 - INFO - 11164 images trouvées.
2017-03-24 17:56:42,500 - ERROR -   File "<stdin>", line 1, in <module>

2017-03-24 17:56:42,503 - ERROR - <type 'exceptions.NameError'> - name 'bt_lecture' is not defined
2017-03-24 17:59:40,901 - ERROR -   File "c:\python27\lib\atexit.py", line 24, in _run_exitfuncs
    func(*targs, **kargs)
  File "c:\python27\lib\site-packages\pymongo\periodic_executor.py", line 167, in _shutdown_executors
    executor.join(1)
  File "c:\python27\lib\site-packages\pymongo\periodic_executor.py", line 96, in join
    self._thread.join(timeout)
  File "c:\python27\lib\threading.py", line 960, in join
    self.__block.wait(delay)
  File "c:\python27\lib\threading.py", line 358, in wait
    _sleep(delay)

2017-03-24 17:59:40,903 - ERROR - <type 'exceptions.KeyboardInterrupt'> - 
2017-03-24 18:55:05,072 - INFO - my_logging logger is started. Console : DEBUG. File (.log) : INFO
2017-03-24 18:55:12,500 - INFO - Lecture des données
2017-03-24 18:55:13,171 - INFO - 22174 mesures trouvées.
2017-03-24 18:55:13,174 - INFO - Correction des moyennes des vitesses angulaires : x:-667, y:-20, z:-226
2017-03-24 18:55:13,233 - INFO - Scan du repertoir images : Q:\Frederic\Gyro ...
2017-03-24 18:55:56,171 - INFO - 11164 images trouvées.
2017-03-24 18:57:01,710 - ERROR -   File "<stdin>", line 1, in <module>

2017-03-24 18:57:01,711 - ERROR - <type 'exceptions.NameError'> - name 'ui_gyro' is not defined
2017-03-24 18:57:30,957 - ERROR -   File "<stdin>", line 1, in <module>

2017-03-24 18:57:30,959 - ERROR - <type 'exceptions.KeyError'> - 0
2017-03-24 18:57:42,637 - ERROR -   File "<stdin>", line 1, in <module>

2017-03-24 18:57:42,638 - ERROR - <type 'exceptions.AttributeError'> - 'gyro_ui' object has no attribute 'self'
2017-03-24 18:57:45,085 - ERROR -   File "<stdin>", line 1, in <module>

2017-03-24 18:57:45,086 - ERROR - <type 'exceptions.KeyError'> - 0
2017-03-24 18:57:50,651 - ERROR -   File "<stdin>", line 1, in <module>

2017-03-24 18:57:50,654 - ERROR - <type 'exceptions.KeyError'> - 0
2017-03-24 18:57:57,052 - ERROR -   File "<stdin>", line 1, in <module>

2017-03-24 18:57:57,052 - ERROR - <type 'exceptions.KeyboardInterrupt'> - 
2017-03-24 18:58:27,275 - ERROR -   File "<stdin>", line 1, in <module>

2017-03-24 18:58:27,276 - ERROR - <type 'exceptions.AttributeError'> - 'gyro_ui' object has no attribute 'images_index'
2017-03-24 18:59:15,351 - ERROR - 
2017-03-24 18:59:15,355 - ERROR - <type 'exceptions.SyntaxError'> - invalid syntax (<stdin>, line 1)
2017-03-24 18:59:31,559 - ERROR -   File "<stdin>", line 1, in <module>

2017-03-24 18:59:31,562 - ERROR - <type 'exceptions.NameError'> - name 'event' is not defined
2017-03-24 18:59:49,687 - ERROR -   File "<stdin>", line 1, in <module>

2017-03-24 18:59:49,687 - ERROR - <type 'exceptions.NameError'> - name 'xdate' is not defined
2017-03-24 19:08:46,381 - ERROR -   File "c:\python27\lib\encodings\cp850.py", line 14, in decode
    def decode(self,input,errors='strict'):

2017-03-24 19:08:46,382 - ERROR - <type 'exceptions.KeyboardInterrupt'> - 
2017-03-24 19:08:50,815 - ERROR -   File "c:\python27\lib\encodings\cp850.py", line 14, in decode
    def decode(self,input,errors='strict'):

2017-03-24 19:08:50,815 - ERROR - <type 'exceptions.KeyboardInterrupt'> - 
2017-03-24 19:08:53,546 - ERROR - 
2017-03-24 19:08:53,549 - ERROR - <type 'exceptions.SyntaxError'> - invalid syntax (<stdin>, line 1)
2018-12-02 12:21:02,400 - INFO - my_logging logger is started. Console : DEBUG. File (.log) : DEBUG at build\bdist.win-amd64\egg\FUTIL\my_logging.py ,line n°:104
2018-12-02 12:21:02,499 - INFO - Lecture des données at FGYRO\gyro_ui.py ,line n°:68
2018-12-02 12:21:02,720 - INFO - 8573 mesures trouvées. at FGYRO\gyro_ui.py ,line n°:83
2018-12-02 12:21:02,721 - INFO - Correction des moyennes des vitesses angulaires : x:-661, y:15, z:-251 at FGYRO\gyro_ui.py ,line n°:98
2018-12-02 12:21:02,736 - ERROR -   File "<stdin>", line 1, in <module>
  File "graphes.py", line 19, in <module>
    my_ui = gyro_ui(mybdd,'c:\\fileurope\\FGYRO\\capture')
  File "FGYRO\gyro_ui.py", line 50, in __init__
    self.lecture_donnees()
  File "FGYRO\gyro_ui.py", line 128, in lecture_donnees
    trig_detect = datetime.timedelta(minutes=10)
 at build\bdist.win-amd64\egg\FUTIL\my_logging.py ,line n°:183
2018-12-02 12:21:02,736 - ERROR - <type 'exceptions.AttributeError'> - type object 'datetime.datetime' has no attribute 'timedelta' at build\bdist.win-amd64\egg\FUTIL\my_logging.py ,line n°:184
2018-12-02 12:22:28,466 - INFO - my_logging logger is started. Console : DEBUG. File (.log) : DEBUG at build\bdist.win-amd64\egg\FUTIL\my_logging.py ,line n°:104
2018-12-02 12:22:28,466 - INFO - my_logging logger is started. Console : DEBUG. File (.log) : DEBUG at build\bdist.win-amd64\egg\FUTIL\my_logging.py ,line n°:104
2018-12-02 12:22:28,471 - INFO - Lecture des données at FGYRO\gyro_ui.py ,line n°:68
2018-12-02 12:22:28,471 - INFO - Lecture des données at FGYRO\gyro_ui.py ,line n°:68
2018-12-02 12:22:28,694 - INFO - 8573 mesures trouvées. at FGYRO\gyro_ui.py ,line n°:83
2018-12-02 12:22:28,694 - INFO - 8573 mesures trouvées. at FGYRO\gyro_ui.py ,line n°:83
2018-12-02 12:22:28,697 - INFO - Correction des moyennes des vitesses angulaires : x:-661, y:15, z:-251 at FGYRO\gyro_ui.py ,line n°:98
2018-12-02 12:22:28,697 - INFO - Correction des moyennes des vitesses angulaires : x:-661, y:15, z:-251 at FGYRO\gyro_ui.py ,line n°:98
2018-12-02 12:22:28,717 - ERROR -   File "<stdin>", line 1, in <module>
  File "graphes.py", line 19, in <module>
    my_ui = gyro_ui(mybdd,'c:\\fileurope\\FGYRO\\capture')
  File "FGYRO\gyro_ui.py", line 50, in __init__
    self.lecture_donnees()
  File "FGYRO\gyro_ui.py", line 128, in lecture_donnees
    trig_detect = datetime.timedelta(minutes=10)
 at build\bdist.win-amd64\egg\FUTIL\my_logging.py ,line n°:183
2018-12-02 12:22:28,717 - ERROR -   File "<stdin>", line 1, in <module>
  File "graphes.py", line 19, in <module>
    my_ui = gyro_ui(mybdd,'c:\\fileurope\\FGYRO\\capture')
  File "FGYRO\gyro_ui.py", line 50, in __init__
    self.lecture_donnees()
  File "FGYRO\gyro_ui.py", line 128, in lecture_donnees
    trig_detect = datetime.timedelta(minutes=10)
 at build\bdist.win-amd64\egg\FUTIL\my_logging.py ,line n°:183
2018-12-02 12:22:28,720 - ERROR - <type 'exceptions.AttributeError'> - type object 'datetime.datetime' has no attribute 'timedelta' at build\bdist.win-amd64\egg\FUTIL\my_logging.py ,line n°:184
2018-12-02 12:22:28,720 - ERROR - <type 'exceptions.AttributeError'> - type object 'datetime.datetime' has no attribute 'timedelta' at build\bdist.win-amd64\egg\FUTIL\my_logging.py ,line n°:184
2018-12-02 12:24:31,109 - ERROR -   File "C:\Python27\lib\atexit.py", line 24, in _run_exitfuncs
    func(*targs, **kargs)
  File "C:\Python27\lib\site-packages\pymongo\periodic_executor.py", line 170, in _shutdown_executors
    executor.join(1)
  File "C:\Python27\lib\site-packages\pymongo\periodic_executor.py", line 96, in join
    self._thread.join(timeout)
  File "C:\Python27\lib\threading.py", line 951, in join
    self.__block.wait(delay)
  File "C:\Python27\lib\threading.py", line 359, in wait
    _sleep(delay)
 at build\bdist.win-amd64\egg\FUTIL\my_logging.py ,line n°:183
2018-12-02 12:24:31,109 - ERROR -   File "C:\Python27\lib\atexit.py", line 24, in _run_exitfuncs
    func(*targs, **kargs)
  File "C:\Python27\lib\site-packages\pymongo\periodic_executor.py", line 170, in _shutdown_executors
    executor.join(1)
  File "C:\Python27\lib\site-packages\pymongo\periodic_executor.py", line 96, in join
    self._thread.join(timeout)
  File "C:\Python27\lib\threading.py", line 951, in join
    self.__block.wait(delay)
  File "C:\Python27\lib\threading.py", line 359, in wait
    _sleep(delay)
 at build\bdist.win-amd64\egg\FUTIL\my_logging.py ,line n°:183
2018-12-02 12:24:31,122 - ERROR - <type 'exceptions.KeyboardInterrupt'> -  at build\bdist.win-amd64\egg\FUTIL\my_logging.py ,line n°:184
2018-12-02 12:24:31,122 - ERROR - <type 'exceptions.KeyboardInterrupt'> -  at build\bdist.win-amd64\egg\FUTIL\my_logging.py ,line n°:184
2018-12-02 12:24:37,930 - INFO - my_logging logger is started. Console : DEBUG. File (.log) : DEBUG at build\bdist.win-amd64\egg\FUTIL\my_logging.py ,line n°:104
2018-12-02 12:24:38,026 - INFO - Lecture des données at FGYRO\gyro_ui.py ,line n°:68
2018-12-02 12:24:38,266 - INFO - 8573 mesures trouvées. at FGYRO\gyro_ui.py ,line n°:83
2018-12-02 12:24:38,267 - INFO - Correction des moyennes des vitesses angulaires : x:-661, y:15, z:-251 at FGYRO\gyro_ui.py ,line n°:98
2018-12-02 12:24:38,280 - ERROR -   File "<stdin>", line 1, in <module>
  File "graphes.py", line 19, in <module>
    my_ui = gyro_ui(mybdd,'c:\\fileurope\\FGYRO\\capture')
  File "FGYRO\gyro_ui.py", line 50, in __init__
    self.lecture_donnees()
  File "FGYRO\gyro_ui.py", line 128, in lecture_donnees
    trig_detect = datetime.timedelta(minutes=10)
 at build\bdist.win-amd64\egg\FUTIL\my_logging.py ,line n°:183
2018-12-02 12:24:38,282 - ERROR - <type 'exceptions.AttributeError'> - type object 'datetime.datetime' has no attribute 'timedelta' at build\bdist.win-amd64\egg\FUTIL\my_logging.py ,line n°:184
2018-12-02 12:24:50,707 - ERROR -   File "<stdin>", line 1, in <module>
 at build\bdist.win-amd64\egg\FUTIL\my_logging.py ,line n°:183
2018-12-02 12:24:50,707 - ERROR - <type 'exceptions.NameError'> - name 'datetime' is not defined at build\bdist.win-amd64\egg\FUTIL\my_logging.py ,line n°:184
2018-12-02 12:25:28,414 - INFO - my_logging logger is started. Console : DEBUG. File (.log) : DEBUG at build\bdist.win-amd64\egg\FUTIL\my_logging.py ,line n°:104
2018-12-02 12:25:28,526 - INFO - Lecture des données at FGYRO\gyro_ui.py ,line n°:67
2018-12-02 12:25:28,829 - INFO - 8573 mesures trouvées. at FGYRO\gyro_ui.py ,line n°:82
2018-12-02 12:25:28,831 - INFO - Correction des moyennes des vitesses angulaires : x:-661, y:15, z:-251 at FGYRO\gyro_ui.py ,line n°:97
2018-12-02 12:25:28,861 - ERROR -   File "<stdin>", line 1, in <module>
  File "graphes.py", line 19, in <module>
    my_ui = gyro_ui(mybdd,'c:\\fileurope\\FGYRO\\capture')
  File "FGYRO\gyro_ui.py", line 49, in __init__
    self.lecture_donnees()
  File "FGYRO\gyro_ui.py", line 127, in lecture_donnees
    trig_detect = datetime.timedelta(minutes=10)
 at build\bdist.win-amd64\egg\FUTIL\my_logging.py ,line n°:183
2018-12-02 12:25:28,862 - ERROR - <type 'exceptions.AttributeError'> - type object 'datetime.datetime' has no attribute 'timedelta' at build\bdist.win-amd64\egg\FUTIL\my_logging.py ,line n°:184
2018-12-02 12:27:50,532 - ERROR -   File "C:\Python27\lib\atexit.py", line 24, in _run_exitfuncs
    func(*targs, **kargs)
  File "C:\Python27\lib\site-packages\pymongo\periodic_executor.py", line 170, in _shutdown_executors
    executor.join(1)
  File "C:\Python27\lib\site-packages\pymongo\periodic_executor.py", line 96, in join
    self._thread.join(timeout)
  File "C:\Python27\lib\threading.py", line 951, in join
    self.__block.wait(delay)
  File "C:\Python27\lib\threading.py", line 359, in wait
    _sleep(delay)
 at build\bdist.win-amd64\egg\FUTIL\my_logging.py ,line n°:183
2018-12-02 12:27:50,536 - ERROR - <type 'exceptions.KeyboardInterrupt'> -  at build\bdist.win-amd64\egg\FUTIL\my_logging.py ,line n°:184
2018-12-02 12:27:55,312 - INFO - my_logging logger is started. Console : DEBUG. File (.log) : DEBUG at build\bdist.win-amd64\egg\FUTIL\my_logging.py ,line n°:104
2018-12-02 12:27:55,407 - INFO - Lecture des données at FGYRO\gyro_ui.py ,line n°:67
2018-12-02 12:27:55,627 - INFO - 8573 mesures trouvées. at FGYRO\gyro_ui.py ,line n°:82
2018-12-02 12:27:55,628 - INFO - Correction des moyennes des vitesses angulaires : x:-661, y:15, z:-251 at FGYRO\gyro_ui.py ,line n°:97
2018-12-02 12:27:55,641 - ERROR -   File "<stdin>", line 1, in <module>
  File "graphes.py", line 19, in <module>
    my_ui = gyro_ui(mybdd,'c:\\fileurope\\FGYRO\\capture')
  File "FGYRO\gyro_ui.py", line 49, in __init__
    self.lecture_donnees()
  File "FGYRO\gyro_ui.py", line 130, in lecture_donnees
    while index<len(self.dates):
 at build\bdist.win-amd64\egg\FUTIL\my_logging.py ,line n°:183
2018-12-02 12:27:55,641 - ERROR - <type 'exceptions.NameError'> - global name 'index' is not defined at build\bdist.win-amd64\egg\FUTIL\my_logging.py ,line n°:184
2018-12-02 12:28:19,624 - INFO - my_logging logger is started. Console : DEBUG. File (.log) : DEBUG at build\bdist.win-amd64\egg\FUTIL\my_logging.py ,line n°:104
2018-12-02 12:28:19,624 - INFO - my_logging logger is started. Console : DEBUG. File (.log) : DEBUG at build\bdist.win-amd64\egg\FUTIL\my_logging.py ,line n°:104
2018-12-02 12:28:19,631 - INFO - Lecture des données at FGYRO\gyro_ui.py ,line n°:67
2018-12-02 12:28:19,631 - INFO - Lecture des données at FGYRO\gyro_ui.py ,line n°:67
2018-12-02 12:28:19,857 - INFO - 8573 mesures trouvées. at FGYRO\gyro_ui.py ,line n°:82
2018-12-02 12:28:19,857 - INFO - 8573 mesures trouvées. at FGYRO\gyro_ui.py ,line n°:82
2018-12-02 12:28:19,858 - INFO - Correction des moyennes des vitesses angulaires : x:-661, y:15, z:-251 at FGYRO\gyro_ui.py ,line n°:97
2018-12-02 12:28:19,858 - INFO - Correction des moyennes des vitesses angulaires : x:-661, y:15, z:-251 at FGYRO\gyro_ui.py ,line n°:97
2018-12-02 12:28:19,877 - ERROR -   File "<stdin>", line 1, in <module>
  File "graphes.py", line 19, in <module>
    my_ui = gyro_ui(mybdd,'c:\\fileurope\\FGYRO\\capture')
  File "FGYRO\gyro_ui.py", line 49, in __init__
    self.lecture_donnees()
  File "FGYRO\gyro_ui.py", line 130, in lecture_donnees
    while i<len(self.dates):
 at build\bdist.win-amd64\egg\FUTIL\my_logging.py ,line n°:183
2018-12-02 12:28:19,877 - ERROR -   File "<stdin>", line 1, in <module>
  File "graphes.py", line 19, in <module>
    my_ui = gyro_ui(mybdd,'c:\\fileurope\\FGYRO\\capture')
  File "FGYRO\gyro_ui.py", line 49, in __init__
    self.lecture_donnees()
  File "FGYRO\gyro_ui.py", line 130, in lecture_donnees
    while i<len(self.dates):
 at build\bdist.win-amd64\egg\FUTIL\my_logging.py ,line n°:183
2018-12-02 12:28:19,878 - ERROR - <type 'exceptions.NameError'> - global name 'index' is not defined at build\bdist.win-amd64\egg\FUTIL\my_logging.py ,line n°:184
2018-12-02 12:28:19,878 - ERROR - <type 'exceptions.NameError'> - global name 'index' is not defined at build\bdist.win-amd64\egg\FUTIL\my_logging.py ,line n°:184
2018-12-02 12:28:23,253 - ERROR -   File "C:\Python27\lib\atexit.py", line 24, in _run_exitfuncs
    func(*targs, **kargs)
  File "C:\Python27\lib\site-packages\pymongo\periodic_executor.py", line 170, in _shutdown_executors
    executor.join(1)
  File "C:\Python27\lib\site-packages\pymongo\periodic_executor.py", line 96, in join
    self._thread.join(timeout)
  File "C:\Python27\lib\threading.py", line 951, in join
    self.__block.wait(delay)
  File "C:\Python27\lib\threading.py", line 359, in wait
    _sleep(delay)
 at build\bdist.win-amd64\egg\FUTIL\my_logging.py ,line n°:183
2018-12-02 12:28:23,253 - ERROR -   File "C:\Python27\lib\atexit.py", line 24, in _run_exitfuncs
    func(*targs, **kargs)
  File "C:\Python27\lib\site-packages\pymongo\periodic_executor.py", line 170, in _shutdown_executors
    executor.join(1)
  File "C:\Python27\lib\site-packages\pymongo\periodic_executor.py", line 96, in join
    self._thread.join(timeout)
  File "C:\Python27\lib\threading.py", line 951, in join
    self.__block.wait(delay)
  File "C:\Python27\lib\threading.py", line 359, in wait
    _sleep(delay)
 at build\bdist.win-amd64\egg\FUTIL\my_logging.py ,line n°:183
2018-12-02 12:28:23,257 - ERROR - <type 'exceptions.KeyboardInterrupt'> -  at build\bdist.win-amd64\egg\FUTIL\my_logging.py ,line n°:184
2018-12-02 12:28:23,257 - ERROR - <type 'exceptions.KeyboardInterrupt'> -  at build\bdist.win-amd64\egg\FUTIL\my_logging.py ,line n°:184
2018-12-02 12:28:27,424 - INFO - my_logging logger is started. Console : DEBUG. File (.log) : DEBUG at build\bdist.win-amd64\egg\FUTIL\my_logging.py ,line n°:104
2018-12-02 12:28:27,522 - INFO - Lecture des données at FGYRO\gyro_ui.py ,line n°:67
2018-12-02 12:28:27,739 - INFO - 8573 mesures trouvées. at FGYRO\gyro_ui.py ,line n°:82
2018-12-02 12:28:27,740 - INFO - Correction des moyennes des vitesses angulaires : x:-661, y:15, z:-251 at FGYRO\gyro_ui.py ,line n°:97
2018-12-02 12:28:27,755 - ERROR -   File "<stdin>", line 1, in <module>
  File "graphes.py", line 19, in <module>
    my_ui = gyro_ui(mybdd,'c:\\fileurope\\FGYRO\\capture')
  File "FGYRO\gyro_ui.py", line 49, in __init__
    self.lecture_donnees()
  File "FGYRO\gyro_ui.py", line 143, in lecture_donnees
    self.phases.append({'debut' : date_debut_mouvement, 'fin' : date_fin_mouvement, 'acceleration_max' : acceleration_max})
 at build\bdist.win-amd64\egg\FUTIL\my_logging.py ,line n°:183
2018-12-02 12:28:27,756 - ERROR - <type 'exceptions.NameError'> - global name 'date_debut_mouvement' is not defined at build\bdist.win-amd64\egg\FUTIL\my_logging.py ,line n°:184
2018-12-02 12:29:48,486 - ERROR -   File "C:\Python27\lib\atexit.py", line 24, in _run_exitfuncs
    func(*targs, **kargs)
  File "C:\Python27\lib\site-packages\pymongo\periodic_executor.py", line 170, in _shutdown_executors
    executor.join(1)
  File "C:\Python27\lib\site-packages\pymongo\periodic_executor.py", line 96, in join
    self._thread.join(timeout)
  File "C:\Python27\lib\threading.py", line 951, in join
    self.__block.wait(delay)
  File "C:\Python27\lib\threading.py", line 359, in wait
    _sleep(delay)
 at build\bdist.win-amd64\egg\FUTIL\my_logging.py ,line n°:183
2018-12-02 12:29:48,490 - ERROR - <type 'exceptions.KeyboardInterrupt'> -  at build\bdist.win-amd64\egg\FUTIL\my_logging.py ,line n°:184
2018-12-02 12:29:50,976 - INFO - my_logging logger is started. Console : DEBUG. File (.log) : DEBUG at build\bdist.win-amd64\egg\FUTIL\my_logging.py ,line n°:104
2018-12-02 12:29:51,072 - INFO - Lecture des données at FGYRO\gyro_ui.py ,line n°:67
2018-12-02 12:29:51,298 - INFO - 8573 mesures trouvées. at FGYRO\gyro_ui.py ,line n°:82
2018-12-02 12:29:51,299 - INFO - Correction des moyennes des vitesses angulaires : x:-661, y:15, z:-251 at FGYRO\gyro_ui.py ,line n°:97
2018-12-02 12:29:51,318 - INFO - Scan du repertoir images : c:\fileurope\FGYRO\capture ... at FGYRO\gyro_ui.py ,line n°:214
2018-12-02 12:29:52,104 - INFO - 6638 images trouvées. at FGYRO\gyro_ui.py ,line n°:226
2018-12-02 12:30:05,358 - ERROR -   File "<stdin>", line 1, in <module>
 at build\bdist.win-amd64\egg\FUTIL\my_logging.py ,line n°:183
2018-12-02 12:30:05,361 - ERROR - <type 'exceptions.NameError'> - name 'dd' is not defined at build\bdist.win-amd64\egg\FUTIL\my_logging.py ,line n°:184
2018-12-02 12:34:37,118 - ERROR -   File "<stdin>", line 1, in <module>
 at build\bdist.win-amd64\egg\FUTIL\my_logging.py ,line n°:183
2018-12-02 12:34:37,118 - ERROR - <type 'exceptions.ImportError'> - No module named xlsxwriter at build\bdist.win-amd64\egg\FUTIL\my_logging.py ,line n°:184
2018-12-02 12:48:52,888 - INFO - my_logging logger is started. Console : DEBUG. File (.log) : DEBUG at build\bdist.win-amd64\egg\FUTIL\my_logging.py ,line n°:104
2018-12-02 12:48:53,028 - INFO - Lecture des données at FGYRO\gyro_ui.py ,line n°:67
2018-12-02 12:48:53,243 - INFO - 8573 mesures trouvées. at FGYRO\gyro_ui.py ,line n°:82
2018-12-02 12:48:53,244 - INFO - Correction des moyennes des vitesses angulaires : x:-661, y:15, z:-251 at FGYRO\gyro_ui.py ,line n°:97
2018-12-02 12:48:53,836 - INFO - Scan du repertoir images : c:\fileurope\FGYRO\capture ... at FGYRO\gyro_ui.py ,line n°:234
2018-12-02 12:48:54,614 - INFO - 6638 images trouvées. at FGYRO\gyro_ui.py ,line n°:246
2018-12-02 12:53:02,398 - INFO - my_logging logger is started. Console : DEBUG. File (.log) : DEBUG at build\bdist.win-amd64\egg\FUTIL\my_logging.py ,line n°:104
2018-12-02 12:53:02,500 - INFO - Lecture des données at FGYRO\gyro_ui.py ,line n°:67
2018-12-02 12:53:02,724 - INFO - 8573 mesures trouvées. at FGYRO\gyro_ui.py ,line n°:82
2018-12-02 12:53:02,726 - INFO - Correction des moyennes des vitesses angulaires : x:-661, y:15, z:-251 at FGYRO\gyro_ui.py ,line n°:97
2018-12-02 12:53:02,799 - ERROR -   File "<stdin>", line 1, in <module>
  File "graphes.py", line 19, in <module>
    my_ui = gyro_ui(mybdd,'c:\\fileurope\\FGYRO\\capture')
  File "FGYRO\gyro_ui.py", line 49, in __init__
    self.lecture_donnees()
  File "FGYRO\gyro_ui.py", line 146, in lecture_donnees
    self.export_xls()
  File "FGYRO\gyro_ui.py", line 166, in export_xls
    workbook.close()
  File "C:\Python27\lib\site-packages\xlsxwriter\workbook.py", line 306, in close
    self._store_workbook()
  File "C:\Python27\lib\site-packages\xlsxwriter\workbook.py", line 655, in _store_workbook
    allowZip64=self.allow_zip64)
  File "C:\Python27\lib\zipfile.py", line 756, in __init__
    self.fp = open(file, modeDict[mode])
 at build\bdist.win-amd64\egg\FUTIL\my_logging.py ,line n°:183
2018-12-02 12:53:02,799 - ERROR - <type 'exceptions.IOError'> - [Errno 13] Permission denied: 'gyro.xlsx' at build\bdist.win-amd64\egg\FUTIL\my_logging.py ,line n°:184
2018-12-02 12:53:26,273 - ERROR -   File "<stdin>", line 1, in <module>
 at build\bdist.win-amd64\egg\FUTIL\my_logging.py ,line n°:183
2018-12-02 12:53:26,273 - ERROR - <type 'exceptions.NameError'> - name 'ui_gyro' is not defined at build\bdist.win-amd64\egg\FUTIL\my_logging.py ,line n°:184
2018-12-02 12:53:37,263 - ERROR -   File "<stdin>", line 1, in <module>
 at build\bdist.win-amd64\egg\FUTIL\my_logging.py ,line n°:183
2018-12-02 12:53:37,266 - ERROR - <type 'exceptions.NameError'> - name 'gyro_ui' is not defined at build\bdist.win-amd64\egg\FUTIL\my_logging.py ,line n°:184
2018-12-02 12:53:49,822 - ERROR -   File "<stdin>", line 1, in <module>
 at build\bdist.win-amd64\egg\FUTIL\my_logging.py ,line n°:183
2018-12-02 12:53:49,828 - ERROR - <type 'exceptions.NameError'> - name 'my_ui' is not defined at build\bdist.win-amd64\egg\FUTIL\my_logging.py ,line n°:184
2018-12-02 12:53:53,584 - ERROR -   File "C:\Python27\lib\atexit.py", line 24, in _run_exitfuncs
    func(*targs, **kargs)
  File "C:\Python27\lib\site-packages\matplotlib\_pylab_helpers.py", line 82, in destroy_all
    gc.collect(1)
 at build\bdist.win-amd64\egg\FUTIL\my_logging.py ,line n°:183
2018-12-02 12:53:53,586 - ERROR - <type 'exceptions.KeyboardInterrupt'> -  at build\bdist.win-amd64\egg\FUTIL\my_logging.py ,line n°:184
2018-12-02 12:54:00,263 - INFO - my_logging logger is started. Console : DEBUG. File (.log) : DEBUG at build\bdist.win-amd64\egg\FUTIL\my_logging.py ,line n°:104
2018-12-02 12:54:00,361 - INFO - Lecture des données at FGYRO\gyro_ui.py ,line n°:67
2018-12-02 12:54:00,598 - INFO - 8573 mesures trouvées. at FGYRO\gyro_ui.py ,line n°:82
2018-12-02 12:54:00,601 - INFO - Correction des moyennes des vitesses angulaires : x:-661, y:15, z:-251 at FGYRO\gyro_ui.py ,line n°:97
2018-12-02 12:54:00,678 - INFO - Scan du repertoir images : c:\fileurope\FGYRO\capture ... at FGYRO\gyro_ui.py ,line n°:235
2018-12-02 12:54:01,697 - INFO - 6638 images trouvées. at FGYRO\gyro_ui.py ,line n°:247
2018-12-02 12:55:57,466 - ERROR -   File "<stdin>", line 1, in <module>
  File "graphes.py", line 20, in <module>
    my_ui.run()
  File "FGYRO\gyro_ui.py", line 62, in run
    plt.show()
  File "C:\Python27\lib\site-packages\matplotlib\pyplot.py", line 253, in show
    return _show(*args, **kw)
  File "C:\Python27\lib\site-packages\matplotlib\backend_bases.py", line 208, in show
    cls.mainloop()
  File "C:\Python27\lib\site-packages\matplotlib\backends\_backend_tk.py", line 1075, in mainloop
    Tk.mainloop()
  File "C:\Python27\lib\lib-tk\Tkinter.py", line 419, in mainloop
    _default_root.tk.mainloop(n)
 at build\bdist.win-amd64\egg\FUTIL\my_logging.py ,line n°:183
2018-12-02 12:55:57,467 - ERROR - <type 'exceptions.KeyboardInterrupt'> -  at build\bdist.win-amd64\egg\FUTIL\my_logging.py ,line n°:184
2018-12-02 12:55:59,973 - ERROR -   File "C:\Python27\lib\atexit.py", line 24, in _run_exitfuncs
    func(*targs, **kargs)
  File "C:\Python27\lib\site-packages\matplotlib\_pylab_helpers.py", line 78, in destroy_all
    manager.destroy()
  File "C:\Python27\lib\site-packages\matplotlib\backends\_backend_tk.py", line 560, in destroy
    self.window.destroy()
  File "C:\Python27\lib\lib-tk\Tkinter.py", line 1863, in destroy
    for c in self.children.values(): c.destroy()
  File "C:\Python27\lib\site-packages\matplotlib\backends\_backend_tk.py", line 658, in destroy
    Tk.Frame.destroy(self, *args)
  File "C:\Python27\lib\lib-tk\Tkinter.py", line 2100, in destroy
    for c in self.children.values(): c.destroy()
  File "C:\Python27\lib\lib-tk\Tkinter.py", line 2101, in destroy
    self.tk.call('destroy', self._w)
 at build\bdist.win-amd64\egg\FUTIL\my_logging.py ,line n°:183
2018-12-02 12:55:59,976 - ERROR - <type 'exceptions.KeyboardInterrupt'> -  at build\bdist.win-amd64\egg\FUTIL\my_logging.py ,line n°:184
2018-12-02 12:56:22,467 - INFO - my_logging logger is started. Console : DEBUG. File (.log) : DEBUG at build\bdist.win-amd64\egg\FUTIL\my_logging.py ,line n°:104
2018-12-02 12:56:22,601 - INFO - Lecture des données at FGYRO\gyro_ui.py ,line n°:67
2018-12-02 12:56:22,825 - INFO - 8573 mesures trouvées. at FGYRO\gyro_ui.py ,line n°:82
2018-12-02 12:56:22,825 - INFO - Correction des moyennes des vitesses angulaires : x:-661, y:15, z:-251 at FGYRO\gyro_ui.py ,line n°:97
2018-12-02 12:56:22,869 - ERROR -   File "<stdin>", line 1, in <module>
  File "graphes.py", line 19, in <module>
    my_ui = gyro_ui(mybdd,'c:\\fileurope\\FGYRO\\capture')
  File "FGYRO\gyro_ui.py", line 49, in __init__
    self.lecture_donnees()
  File "FGYRO\gyro_ui.py", line 146, in lecture_donnees
    self.export_xls()
  File "FGYRO\gyro_ui.py", line 163, in export_xls
    worksheet.write(row, col, str(self.phases[key]))
 at build\bdist.win-amd64\egg\FUTIL\my_logging.py ,line n°:183
2018-12-02 12:56:22,871 - ERROR - <type 'exceptions.TypeError'> - list indices must be integers, not str at build\bdist.win-amd64\egg\FUTIL\my_logging.py ,line n°:184
2018-12-02 12:57:15,641 - ERROR -   File "C:\Python27\lib\atexit.py", line 24, in _run_exitfuncs
    func(*targs, **kargs)
  File "C:\Python27\lib\site-packages\pymongo\periodic_executor.py", line 170, in _shutdown_executors
    executor.join(1)
  File "C:\Python27\lib\site-packages\pymongo\periodic_executor.py", line 96, in join
    self._thread.join(timeout)
  File "C:\Python27\lib\threading.py", line 930, in join
    if self is current_thread():
  File "C:\Python27\lib\threading.py", line 1151, in currentThread
    return _active[_get_ident()]
 at build\bdist.win-amd64\egg\FUTIL\my_logging.py ,line n°:183
2018-12-02 12:57:15,644 - ERROR - <type 'exceptions.KeyboardInterrupt'> -  at build\bdist.win-amd64\egg\FUTIL\my_logging.py ,line n°:184
2018-12-02 12:57:19,872 - INFO - my_logging logger is started. Console : DEBUG. File (.log) : DEBUG at build\bdist.win-amd64\egg\FUTIL\my_logging.py ,line n°:104
2018-12-02 12:57:19,970 - INFO - Lecture des données at FGYRO\gyro_ui.py ,line n°:67
2018-12-02 12:57:20,186 - INFO - 8573 mesures trouvées. at FGYRO\gyro_ui.py ,line n°:82
2018-12-02 12:57:20,187 - INFO - Correction des moyennes des vitesses angulaires : x:-661, y:15, z:-251 at FGYRO\gyro_ui.py ,line n°:97
2018-12-02 12:57:20,266 - INFO - Scan du repertoir images : c:\fileurope\FGYRO\capture ... at FGYRO\gyro_ui.py ,line n°:235
2018-12-02 12:57:21,101 - INFO - 6638 images trouvées. at FGYRO\gyro_ui.py ,line n°:247
2018-12-02 12:59:50,312 - ERROR -   File "<stdin>", line 1, in <module>
  File "graphes.py", line 20, in <module>
    my_ui.run()
  File "FGYRO\gyro_ui.py", line 62, in run
    plt.show()
  File "C:\Python27\lib\site-packages\matplotlib\pyplot.py", line 253, in show
    return _show(*args, **kw)
  File "C:\Python27\lib\site-packages\matplotlib\backend_bases.py", line 208, in show
    cls.mainloop()
  File "C:\Python27\lib\site-packages\matplotlib\backends\_backend_tk.py", line 1075, in mainloop
    Tk.mainloop()
  File "C:\Python27\lib\lib-tk\Tkinter.py", line 419, in mainloop
    _default_root.tk.mainloop(n)
 at build\bdist.win-amd64\egg\FUTIL\my_logging.py ,line n°:183
2018-12-02 12:59:50,315 - ERROR - <type 'exceptions.KeyboardInterrupt'> -  at build\bdist.win-amd64\egg\FUTIL\my_logging.py ,line n°:184
2018-12-02 12:59:57,582 - INFO - my_logging logger is started. Console : DEBUG. File (.log) : DEBUG at build\bdist.win-amd64\egg\FUTIL\my_logging.py ,line n°:104
2018-12-02 12:59:57,680 - INFO - Lecture des données at FGYRO\gyro_ui.py ,line n°:67
2018-12-02 12:59:57,905 - INFO - 8573 mesures trouvées. at FGYRO\gyro_ui.py ,line n°:82
2018-12-02 12:59:57,907 - INFO - Correction des moyennes des vitesses angulaires : x:-661, y:15, z:-251 at FGYRO\gyro_ui.py ,line n°:97
2018-12-02 12:59:58,006 - INFO - Scan du repertoir images : c:\fileurope\FGYRO\capture ... at FGYRO\gyro_ui.py ,line n°:235
2018-12-02 12:59:58,733 - INFO - 6638 images trouvées. at FGYRO\gyro_ui.py ,line n°:247
2018-12-02 13:06:32,658 - ERROR -   File "<stdin>", line 1, in <module>
  File "graphes.py", line 20, in <module>
    my_ui.run()
  File "FGYRO\gyro_ui.py", line 62, in run
    plt.show()
  File "C:\Python27\lib\site-packages\matplotlib\pyplot.py", line 253, in show
    return _show(*args, **kw)
  File "C:\Python27\lib\site-packages\matplotlib\backend_bases.py", line 208, in show
    cls.mainloop()
  File "C:\Python27\lib\site-packages\matplotlib\backends\_backend_tk.py", line 1075, in mainloop
    Tk.mainloop()
  File "C:\Python27\lib\lib-tk\Tkinter.py", line 419, in mainloop
    _default_root.tk.mainloop(n)
 at build\bdist.win-amd64\egg\FUTIL\my_logging.py ,line n°:183
2018-12-02 13:06:32,661 - ERROR - <type 'exceptions.KeyboardInterrupt'> -  at build\bdist.win-amd64\egg\FUTIL\my_logging.py ,line n°:184
2018-12-02 13:06:34,170 - ERROR -   File "C:\Python27\lib\atexit.py", line 24, in _run_exitfuncs
    func(*targs, **kargs)
  File "C:\Python27\lib\site-packages\matplotlib\_pylab_helpers.py", line 78, in destroy_all
    manager.destroy()
  File "C:\Python27\lib\site-packages\matplotlib\backends\_backend_tk.py", line 560, in destroy
    self.window.destroy()
  File "C:\Python27\lib\lib-tk\Tkinter.py", line 1863, in destroy
    for c in self.children.values(): c.destroy()
  File "C:\Python27\lib\site-packages\matplotlib\backends\_backend_tk.py", line 658, in destroy
    Tk.Frame.destroy(self, *args)
  File "C:\Python27\lib\lib-tk\Tkinter.py", line 2100, in destroy
    for c in self.children.values(): c.destroy()
  File "C:\Python27\lib\lib-tk\Tkinter.py", line 2101, in destroy
    self.tk.call('destroy', self._w)
 at build\bdist.win-amd64\egg\FUTIL\my_logging.py ,line n°:183
2018-12-02 13:06:34,174 - ERROR - <type 'exceptions.KeyboardInterrupt'> -  at build\bdist.win-amd64\egg\FUTIL\my_logging.py ,line n°:184
2018-12-02 13:07:25,920 - INFO - my_logging logger is started. Console : DEBUG. File (.log) : DEBUG at build\bdist.win-amd64\egg\FUTIL\my_logging.py ,line n°:104
2018-12-02 13:07:26,072 - INFO - Lecture des données at FGYRO\gyro_ui.py ,line n°:67
2018-12-02 13:07:26,296 - INFO - 8573 mesures trouvées. at FGYRO\gyro_ui.py ,line n°:82
2018-12-02 13:07:26,299 - INFO - Correction des moyennes des vitesses angulaires : x:-661, y:15, z:-251 at FGYRO\gyro_ui.py ,line n°:97
2018-12-02 13:07:26,381 - INFO - Scan du repertoir images : c:\fileurope\FGYRO\capture ... at FGYRO\gyro_ui.py ,line n°:239
2018-12-02 13:07:27,348 - INFO - 6638 images trouvées. at FGYRO\gyro_ui.py ,line n°:251
2018-12-02 13:14:49,762 - ERROR -   File "<stdin>", line 1, in <module>
  File "graphes.py", line 20, in <module>
    my_ui.run()
  File "FGYRO\gyro_ui.py", line 62, in run
    plt.show()
  File "C:\Python27\lib\site-packages\matplotlib\pyplot.py", line 253, in show
    return _show(*args, **kw)
  File "C:\Python27\lib\site-packages\matplotlib\backend_bases.py", line 208, in show
    cls.mainloop()
  File "C:\Python27\lib\site-packages\matplotlib\backends\_backend_tk.py", line 1075, in mainloop
    Tk.mainloop()
  File "C:\Python27\lib\lib-tk\Tkinter.py", line 419, in mainloop
    _default_root.tk.mainloop(n)
 at build\bdist.win-amd64\egg\FUTIL\my_logging.py ,line n°:183
2018-12-02 13:14:49,763 - ERROR - <type 'exceptions.KeyboardInterrupt'> -  at build\bdist.win-amd64\egg\FUTIL\my_logging.py ,line n°:184
2018-12-02 13:16:04,299 - ERROR -   File "<stdin>", line 1, in <module>
 at build\bdist.win-amd64\egg\FUTIL\my_logging.py ,line n°:183
2018-12-02 13:16:04,301 - ERROR - <type 'exceptions.NameError'> - name 'xlswriter' is not defined at build\bdist.win-amd64\egg\FUTIL\my_logging.py ,line n°:184
2018-12-02 13:16:15,661 - ERROR -   File "<stdin>", line 1, in <module>
 at build\bdist.win-amd64\egg\FUTIL\my_logging.py ,line n°:183
2018-12-02 13:16:15,661 - ERROR - <type 'exceptions.ImportError'> - No module named xlswriter at build\bdist.win-amd64\egg\FUTIL\my_logging.py ,line n°:184
2018-12-02 13:16:50,510 - ERROR -   File "<stdin>", line 1, in <module>
  File "C:\Python27\lib\site.py", line 446, in __call__
    return pydoc.help(*args, **kwds)
  File "C:\Python27\lib\pydoc.py", line 1795, in __call__
    self.help(request)
  File "C:\Python27\lib\pydoc.py", line 1842, in help
    else: doc(request, 'Help on %s:')
  File "C:\Python27\lib\pydoc.py", line 1579, in doc
    pager(render_doc(thing, title, forceload))
  File "C:\Python27\lib\pydoc.py", line 1396, in <lambda>
    return lambda text: tempfilepager(plain(text), 'more <')
  File "C:\Python27\lib\pydoc.py", line 1432, in tempfilepager
    os.system(cmd + ' "' + filename + '"')
 at build\bdist.win-amd64\egg\FUTIL\my_logging.py ,line n°:183
2018-12-02 13:16:50,515 - ERROR - <type 'exceptions.KeyboardInterrupt'> -  at build\bdist.win-amd64\egg\FUTIL\my_logging.py ,line n°:184
2018-12-02 13:17:00,240 - ERROR -   File "<stdin>", line 1, in <module>
 at build\bdist.win-amd64\egg\FUTIL\my_logging.py ,line n°:183
2018-12-02 13:17:00,242 - ERROR - <type 'exceptions.AttributeError'> - 'module' object has no attribute 'write' at build\bdist.win-amd64\egg\FUTIL\my_logging.py ,line n°:184
2018-12-02 13:18:25,013 - ERROR -   File "<stdin>", line 1, in <module>
 at build\bdist.win-amd64\egg\FUTIL\my_logging.py ,line n°:183
2018-12-02 13:18:25,015 - ERROR - <type 'exceptions.AttributeError'> - 'module' object has no attribute 'write' at build\bdist.win-amd64\egg\FUTIL\my_logging.py ,line n°:184
2018-12-02 13:19:47,006 - ERROR -   File "C:\Python27\lib\atexit.py", line 24, in _run_exitfuncs
    func(*targs, **kargs)
  File "C:\Python27\lib\site-packages\pymongo\periodic_executor.py", line 170, in _shutdown_executors
    executor.join(1)
  File "C:\Python27\lib\site-packages\pymongo\periodic_executor.py", line 96, in join
    self._thread.join(timeout)
  File "C:\Python27\lib\threading.py", line 951, in join
    self.__block.wait(delay)
  File "C:\Python27\lib\threading.py", line 359, in wait
    _sleep(delay)
 at build\bdist.win-amd64\egg\FUTIL\my_logging.py ,line n°:183
2018-12-02 13:19:47,009 - ERROR - <type 'exceptions.KeyboardInterrupt'> -  at build\bdist.win-amd64\egg\FUTIL\my_logging.py ,line n°:184
2018-12-02 13:19:58,157 - INFO - my_logging logger is started. Console : DEBUG. File (.log) : DEBUG at build\bdist.win-amd64\egg\FUTIL\my_logging.py ,line n°:104
2018-12-02 13:19:58,295 - INFO - Lecture des données at FGYRO\gyro_ui.py ,line n°:67
2018-12-02 13:19:58,510 - INFO - 8573 mesures trouvées. at FGYRO\gyro_ui.py ,line n°:82
2018-12-02 13:19:58,512 - INFO - Correction des moyennes des vitesses angulaires : x:-661, y:15, z:-251 at FGYRO\gyro_ui.py ,line n°:97
2018-12-02 13:19:58,594 - INFO - Scan du repertoir images : c:\fileurope\FGYRO\capture ... at FGYRO\gyro_ui.py ,line n°:239
2018-12-02 13:19:59,546 - INFO - 6638 images trouvées. at FGYRO\gyro_ui.py ,line n°:251
2018-12-02 13:21:42,877 - ERROR -   File "<stdin>", line 1, in <module>
  File "graphes.py", line 20, in <module>
    my_ui.run()
  File "FGYRO\gyro_ui.py", line 62, in run
    plt.show()
  File "C:\Python27\lib\site-packages\matplotlib\pyplot.py", line 253, in show
    return _show(*args, **kw)
  File "C:\Python27\lib\site-packages\matplotlib\backend_bases.py", line 208, in show
    cls.mainloop()
  File "C:\Python27\lib\site-packages\matplotlib\backends\_backend_tk.py", line 1075, in mainloop
    Tk.mainloop()
  File "C:\Python27\lib\lib-tk\Tkinter.py", line 419, in mainloop
    _default_root.tk.mainloop(n)
 at build\bdist.win-amd64\egg\FUTIL\my_logging.py ,line n°:183
2018-12-02 13:21:42,880 - ERROR - <type 'exceptions.KeyboardInterrupt'> -  at build\bdist.win-amd64\egg\FUTIL\my_logging.py ,line n°:184
2018-12-02 13:21:45,418 - ERROR -   File "C:\Python27\lib\atexit.py", line 24, in _run_exitfuncs
    func(*targs, **kargs)
  File "C:\Python27\lib\site-packages\matplotlib\_pylab_helpers.py", line 78, in destroy_all
    manager.destroy()
  File "C:\Python27\lib\site-packages\matplotlib\backends\_backend_tk.py", line 560, in destroy
    self.window.destroy()
  File "C:\Python27\lib\lib-tk\Tkinter.py", line 1863, in destroy
    for c in self.children.values(): c.destroy()
  File "C:\Python27\lib\site-packages\matplotlib\backends\_backend_tk.py", line 658, in destroy
    Tk.Frame.destroy(self, *args)
  File "C:\Python27\lib\lib-tk\Tkinter.py", line 2100, in destroy
    for c in self.children.values(): c.destroy()
  File "C:\Python27\lib\lib-tk\Tkinter.py", line 2101, in destroy
    self.tk.call('destroy', self._w)
 at build\bdist.win-amd64\egg\FUTIL\my_logging.py ,line n°:183
2018-12-02 13:21:45,434 - ERROR - <type 'exceptions.KeyboardInterrupt'> -  at build\bdist.win-amd64\egg\FUTIL\my_logging.py ,line n°:184
2018-12-02 13:21:52,204 - INFO - my_logging logger is started. Console : DEBUG. File (.log) : DEBUG at build\bdist.win-amd64\egg\FUTIL\my_logging.py ,line n°:104
2018-12-02 13:21:52,302 - INFO - Lecture des données at FGYRO\gyro_ui.py ,line n°:67
2018-12-02 13:21:52,519 - INFO - 8573 mesures trouvées. at FGYRO\gyro_ui.py ,line n°:82
2018-12-02 13:21:52,522 - INFO - Correction des moyennes des vitesses angulaires : x:-661, y:15, z:-251 at FGYRO\gyro_ui.py ,line n°:97
2018-12-02 13:21:52,604 - INFO - Scan du repertoir images : c:\fileurope\FGYRO\capture ... at FGYRO\gyro_ui.py ,line n°:239
2018-12-02 13:21:53,536 - INFO - 6638 images trouvées. at FGYRO\gyro_ui.py ,line n°:251
2019-02-10 11:53:23,040 - INFO - my_logging logger is started. Console : DEBUG. File (.log) : DEBUG
2019-02-10 11:53:23,124 - INFO - FGYRO.main.py start
2019-02-10 11:53:23,206 - INFO - <FGPIO.led_io.led_io object at 0xb62906d0> is created on pin 16 : GPIO en mode OUTPUT. Valeur = 0.
2019-02-10 11:53:23,618 - ERROR -   File "<stdin>", line 1, in <module>
  File "FGYRO/mqtt_camera.py", line 71, in __init__
    self.init_camera()
  File "FGYRO/mqtt_camera.py", line 87, in init_camera
    if self.leds:

2019-02-10 11:53:23,644 - ERROR - <type 'exceptions.AttributeError'> - 'mqtt_camera' object has no attribute 'leds'
2019-02-10 11:54:27,906 - INFO - my_logging logger is started. Console : DEBUG. File (.log) : DEBUG
2019-02-10 11:54:28,066 - INFO - FGYRO.main.py start
2019-02-10 11:54:28,197 - INFO - <FGPIO.led_io.led_io object at 0xb62a96d0> is created on pin 16 : GPIO en mode OUTPUT. Valeur = 0.
2019-02-10 11:54:30,644 - ERROR -   File "<stdin>", line 1, in <module>
  File "FGYRO/mqtt_camera.py", line 74, in __init__
    self.init_camera()
  File "FGYRO/mqtt_camera.py", line 98, in init_camera
    self.thread = f_thread(self._stop_camera)

2019-02-10 11:54:30,675 - ERROR - <type 'exceptions.TypeError'> - 'module' object is not callable
2019-02-10 11:55:45,944 - INFO - my_logging logger is started. Console : DEBUG. File (.log) : DEBUG
2019-02-10 11:55:46,107 - INFO - FGYRO.main.py start
2019-02-10 11:55:46,225 - INFO - <FGPIO.led_io.led_io object at 0xb623d6d0> is created on pin 16 : GPIO en mode OUTPUT. Valeur = 1.
2019-02-10 11:55:48,930 - INFO - f_thread _stop_camera started.
2019-02-10 11:55:53,961 - ERROR -   File "/usr/local/lib/python2.7/dist-packages/FGPIO/f_thread.py", line 40, in run
    self.fonction(*self.args, **self.kwargs)
  File "FGYRO/mqtt_camera.py", line 108, in _stop_camera
    self.stop_camera()
  File "FGYRO/mqtt_camera.py", line 113, in stop_camera
    leds.off()

2019-02-10 11:55:53,986 - ERROR - <type 'exceptions.NameError'> - global name 'leds' is not defined
2019-02-10 11:56:14,521 - ERROR - 
2019-02-10 11:56:14,530 - ERROR - <type 'exceptions.KeyboardInterrupt'> - 
2019-02-10 11:56:29,139 - INFO - my_logging logger is started. Console : DEBUG. File (.log) : DEBUG
2019-02-10 11:56:29,318 - INFO - FGYRO.main.py start
2019-02-10 11:56:29,447 - INFO - <FGPIO.led_io.led_io object at 0xb62dd6d0> is created on pin 16 : GPIO en mode OUTPUT. Valeur = 1.
2019-02-10 11:56:31,345 - INFO - f_thread _stop_camera started.
2019-02-10 11:56:36,344 - ERROR -   File "/usr/local/lib/python2.7/dist-packages/FGPIO/f_thread.py", line 40, in run
    self.fonction(*self.args, **self.kwargs)
  File "FGYRO/mqtt_camera.py", line 108, in _stop_camera
    self.stop_camera()
  File "FGYRO/mqtt_camera.py", line 114, in stop_camera
    self.camera.close()

2019-02-10 11:56:36,365 - ERROR - <type 'exceptions.AttributeError'> - 'NoneType' object has no attribute 'close'
2019-02-10 11:57:33,176 - ERROR - 
2019-02-10 11:57:33,184 - ERROR - <type 'exceptions.KeyboardInterrupt'> - 
2019-02-10 11:57:33,934 - ERROR - 
2019-02-10 11:57:33,940 - ERROR - <type 'exceptions.KeyboardInterrupt'> - 
2019-02-10 11:57:50,302 - INFO - my_logging logger is started. Console : DEBUG. File (.log) : DEBUG
2019-02-10 11:57:50,401 - INFO - FGYRO.main.py start
2019-02-10 11:57:50,514 - INFO - <FGPIO.led_io.led_io object at 0xb62106b0> is created on pin 16 : GPIO en mode OUTPUT. Valeur = 0.
2019-02-10 11:57:52,721 - INFO - f_thread _stop_camera started.
2019-02-10 11:58:21,970 - INFO - f_thread _stop_camera started.
2019-02-10 11:58:56,338 - ERROR -   File "<stdin>", line 1, in <module>

2019-02-10 11:58:56,369 - ERROR - <type 'exceptions.NameError'> - name 'self' is not defined
2019-02-10 11:59:08,979 - INFO - Send terminated order to <f_thread(Thread-2, started -1292897184)>
2019-02-10 11:59:09,018 - INFO - _stop_camera stopped after 54701 loops
2019-02-10 12:00:24,323 - ERROR -   File "<stdin>", line 1, in <module>

2019-02-10 12:00:24,351 - ERROR - <type 'exceptions.NameError'> - name 'self' is not defined
2019-02-10 12:00:43,269 - INFO - f_thread _stop_camera started.
2019-02-10 12:01:04,839 - INFO - f_thread _stop_camera started.
2019-02-10 12:04:41,770 - INFO - my_logging logger is started. Console : DEBUG. File (.log) : DEBUG
2019-02-10 12:04:41,916 - INFO - FGYRO.main.py start
2019-02-10 12:04:42,091 - INFO - <FGPIO.led_io.led_io object at 0xb62ef6b0> is created on pin 16 : GPIO en mode OUTPUT. Valeur = 0.
2019-02-10 12:04:44,616 - INFO - f_thread _stop_camera started.
2019-02-10 12:04:49,617 - DEBUG - Camera stopped.
2019-02-10 12:04:49,643 - INFO - Send terminated order to <f_thread(Thread-1, started -1274096544)>
2019-02-10 12:04:49,681 - INFO - _stop_camera stopped after 46224 loops
2019-02-10 12:05:09,545 - INFO - f_thread _stop_camera started.
2019-02-10 12:05:12,627 - ERROR -   File "<stdin>", line 1, in <module>
  File "FGYRO/mqtt_camera.py", line 101, in init_camera
    time.sleep(self.init_time_camera - time.time() + self.starting_time)

2019-02-10 12:05:12,654 - ERROR - <type 'exceptions.IOError'> - [Errno 22] Invalid argument
2019-02-10 12:05:14,543 - DEBUG - Camera stopped.
2019-02-10 12:05:14,558 - INFO - Send terminated order to <f_thread(Thread-2, started -1274096544)>
2019-02-10 12:05:14,574 - INFO - _stop_camera stopped after 148493 loops
2019-02-10 12:07:06,089 - INFO - my_logging logger is started. Console : DEBUG. File (.log) : DEBUG
2019-02-10 12:07:06,197 - INFO - FGYRO.main.py start
2019-02-10 12:07:06,387 - INFO - <FGPIO.led_io.led_io object at 0xb6677d50> is created on pin 16 : GPIO en mode OUTPUT. Valeur = 0.
2019-02-10 12:07:06,945 - ERROR -   File "<stdin>", line 1, in <module>

2019-02-10 12:07:06,980 - ERROR - <type 'exceptions.NameError'> - name 'mqtt_camera' is not defined
2019-02-10 12:07:54,747 - ERROR - 
2019-02-10 12:07:54,753 - ERROR - <type 'exceptions.KeyboardInterrupt'> - 
2019-02-10 12:08:12,839 - INFO - my_logging logger is started. Console : DEBUG. File (.log) : DEBUG
2019-02-10 12:08:12,962 - INFO - FGYRO.main.py start
2019-02-10 12:08:13,152 - INFO - <FGPIO.led_io.led_io object at 0xb626b6b0> is created on pin 16 : GPIO en mode OUTPUT. Valeur = 0.
2019-02-10 12:08:15,758 - INFO - f_thread _stop_camera started.
2019-02-10 12:08:20,758 - DEBUG - Camera stopped.
2019-02-10 12:08:20,771 - INFO - Send terminated order to <f_thread(Thread-1, started -1274022816)>
2019-02-10 12:08:20,786 - INFO - _stop_camera stopped after 55879 loops
2019-02-10 12:08:24,269 - INFO - f_thread _stop_camera started.
2019-02-10 12:08:29,285 - DEBUG - Camera stopped.
2019-02-10 12:08:29,319 - INFO - Send terminated order to <f_thread(Thread-2, started -1274022816)>
2019-02-10 12:08:29,336 - INFO - _stop_camera stopped after 41418 loops
2019-02-10 12:08:38,080 - INFO - f_thread _stop_camera started.
2019-02-10 12:08:43,081 - DEBUG - Camera stopped.
2019-02-10 12:08:43,106 - INFO - Send terminated order to <f_thread(Thread-3, started -1274022816)>
2019-02-10 12:08:43,140 - INFO - _stop_camera stopped after 36345 loops
2019-02-10 12:08:50,151 - INFO - f_thread _stop_camera started.
2019-02-10 12:08:55,147 - DEBUG - Camera stopped.
2019-02-10 12:08:55,180 - INFO - Send terminated order to <f_thread(Thread-4, started -1274022816)>
2019-02-10 12:08:55,202 - INFO - _stop_camera stopped after 53233 loops
2019-02-10 12:09:46,830 - INFO - f_thread _stop_camera started.
2019-02-10 12:09:51,838 - DEBUG - Camera stopped.
2019-02-10 12:09:51,862 - INFO - Send terminated order to <f_thread(Thread-5, started -1274022816)>
2019-02-10 12:09:51,893 - INFO - _stop_camera stopped after 54644 loops
2019-02-10 12:09:53,767 - INFO - f_thread _stop_camera started.
2019-02-10 12:09:58,784 - DEBUG - Camera stopped.
2019-02-10 12:09:58,801 - INFO - Send terminated order to <f_thread(Thread-6, started -1274022816)>
2019-02-10 12:09:58,842 - INFO - _stop_camera stopped after 46018 loops
2019-02-10 12:13:04,399 - ERROR - 
2019-02-10 12:13:04,407 - ERROR - <type 'exceptions.KeyboardInterrupt'> - 
2019-02-10 12:13:10,553 - INFO - my_logging logger is started. Console : DEBUG. File (.log) : DEBUG
2019-02-10 12:13:10,653 - INFO - FGYRO.main.py start
2019-02-10 12:13:10,747 - INFO - <FGPIO.led_io.led_io object at 0xb62f16b0> is created on pin 16 : GPIO en mode OUTPUT. Valeur = 0.
2019-02-10 12:13:14,432 - DEBUG - Camera starting...
2019-02-10 12:13:17,325 - DEBUG - Camera started.
2019-02-10 12:13:17,349 - INFO - f_thread _stop_camera started.
2019-02-10 12:13:22,325 - DEBUG - Camera stopped.
2019-02-10 12:13:22,339 - INFO - Send terminated order to <f_thread(Thread-1, started -1274022816)>
2019-02-10 12:13:22,361 - INFO - _stop_camera stopped after 142393 loops
2019-02-10 12:13:36,167 - DEBUG - Camera starting...
2019-02-10 12:13:38,888 - DEBUG - Camera started.
2019-02-10 12:13:38,915 - INFO - f_thread _stop_camera started.
2019-02-10 12:13:39,117 - DEBUG - Camera starting in progress...
2019-02-10 12:13:40,410 - DEBUG - Camera starting in progress...
2019-02-10 12:13:43,888 - DEBUG - Camera stopped.
2019-02-10 12:13:43,896 - INFO - Send terminated order to <f_thread(Thread-2, started -1274022816)>
2019-02-10 12:13:43,909 - INFO - _stop_camera stopped after 146243 loops
2019-02-10 12:13:53,680 - DEBUG - Camera starting...
2019-02-10 12:13:56,412 - DEBUG - Camera started.
2019-02-10 12:13:56,443 - DEBUG - Camera starting in progress...
2019-02-10 12:13:56,445 - INFO - f_thread _stop_camera started.
2019-02-10 12:13:57,286 - DEBUG - Camera starting in progress...
2019-02-10 12:14:00,563 - DEBUG - Camera starting in progress...
2019-02-10 12:14:01,416 - DEBUG - Camera stopped.
2019-02-10 12:14:01,430 - INFO - Send terminated order to <f_thread(Thread-3, started -1274022816)>
2019-02-10 12:14:01,446 - INFO - _stop_camera stopped after 144153 loops
2019-02-10 12:17:58,451 - ERROR - 
2019-02-10 12:17:58,462 - ERROR - <type 'exceptions.KeyboardInterrupt'> - 
2019-02-10 12:17:59,018 - ERROR - 
2019-02-10 12:17:59,025 - ERROR - <type 'exceptions.KeyboardInterrupt'> - 
2019-02-10 12:18:15,865 - INFO - my_logging logger is started. Console : DEBUG. File (.log) : DEBUG
2019-02-10 12:18:16,007 - INFO - FGYRO.main.py start
2019-02-10 12:18:16,187 - INFO - <FGPIO.led_io.led_io object at 0xb62a16b0> is created on pin 16 : GPIO en mode OUTPUT. Valeur = 0.
2019-02-10 12:18:18,752 - DEBUG - Camera status : stop.
2019-02-10 12:18:18,801 - DEBUG - Camera status : starting.
2019-02-10 12:18:22,322 - DEBUG - Camera status : starting.
2019-02-10 12:18:22,359 - INFO - f_thread _stop_camera started.
2019-02-10 12:18:27,343 - DEBUG - Camera status : stop.
2019-02-10 12:18:27,370 - INFO - Send terminated order to <f_thread(Thread-1, started -1274022816)>
2019-02-10 12:18:27,395 - INFO - _stop_camera stopped after 37771 loops
2019-02-10 12:18:45,698 - DEBUG - Camera status : stop.
2019-02-10 12:18:45,704 - DEBUG - Camera status : starting.
2019-02-10 12:18:48,456 - DEBUG - Camera status : starting.
2019-02-10 12:18:48,467 - INFO - f_thread _stop_camera started.
2019-02-10 12:18:53,456 - DEBUG - Camera status : stop.
2019-02-10 12:18:53,466 - INFO - Send terminated order to <f_thread(Thread-2, started -1274022816)>
2019-02-10 12:18:53,484 - INFO - _stop_camera stopped after 144851 loops
2019-02-10 12:19:21,821 - DEBUG - Camera status : stop.
2019-02-10 12:19:21,827 - DEBUG - Camera status : starting.
2019-02-10 12:19:24,583 - DEBUG - Camera status : starting.
2019-02-10 12:19:24,604 - INFO - f_thread _stop_camera started.
2019-02-10 12:19:26,820 - DEBUG - Camera status : starting.
2019-02-10 12:19:26,844 - DEBUG - Camera status : starting.
2019-02-10 12:19:29,584 - DEBUG - Camera status : stop.
2019-02-10 12:19:29,591 - INFO - Send terminated order to <f_thread(Thread-3, started -1274022816)>
2019-02-10 12:19:29,615 - INFO - _stop_camera stopped after 136222 loops
2019-02-10 12:20:33,403 - DEBUG - Camera status : stop.
2019-02-10 12:20:33,411 - DEBUG - Camera status : starting.
2019-02-10 12:20:36,143 - DEBUG - Camera status : starting.
2019-02-10 12:20:36,170 - INFO - f_thread _stop_camera started.
2019-02-10 12:20:41,146 - DEBUG - Camera status : stop.
2019-02-10 12:20:41,155 - INFO - Send terminated order to <f_thread(Thread-4, started -1274022816)>
2019-02-10 12:20:41,168 - INFO - _stop_camera stopped after 136621 loops
2019-02-10 12:21:00,221 - ERROR - 
2019-02-10 12:21:00,227 - ERROR - <type 'exceptions.KeyboardInterrupt'> - 
2019-02-10 12:21:17,770 - INFO - my_logging logger is started. Console : DEBUG. File (.log) : DEBUG
2019-02-10 12:21:17,907 - INFO - FGYRO.main.py start
2019-02-10 12:21:18,082 - INFO - <FGPIO.led_io.led_io object at 0xb628c6b0> is created on pin 16 : GPIO en mode OUTPUT. Valeur = 0.
2019-02-10 12:21:18,790 - DEBUG - Camera status : stop.
2019-02-10 12:21:18,813 - DEBUG - Camera status : starting.
2019-02-10 12:21:22,399 - DEBUG - Camera status : start.
2019-02-10 12:21:22,439 - INFO - f_thread _stop_camera started.
2019-02-10 12:21:27,411 - DEBUG - Camera status : stop.
2019-02-10 12:21:27,455 - INFO - Send terminated order to <f_thread(Thread-1, started -1274022816)>
2019-02-10 12:21:27,482 - INFO - _stop_camera stopped after 45496 loops
2019-02-10 12:21:41,835 - DEBUG - Camera status : stop.
2019-02-10 12:21:41,840 - DEBUG - Camera status : starting.
2019-02-10 12:21:44,632 - DEBUG - Camera status : start.
2019-02-10 12:21:44,663 - INFO - f_thread _stop_camera started.
2019-02-10 12:21:44,701 - DEBUG - Camera status : start.
2019-02-10 12:21:44,743 - DEBUG - Camera status : start.
2019-02-10 12:21:45,377 - DEBUG - Camera status : start.
2019-02-10 12:21:45,449 - DEBUG - Camera status : start.
2019-02-10 12:21:48,042 - DEBUG - Camera status : start.
2019-02-10 12:21:48,068 - DEBUG - Camera status : start.
2019-02-10 12:21:50,510 - DEBUG - Camera status : start.
2019-02-10 12:21:50,540 - DEBUG - Camera status : start.
2019-02-10 12:21:52,931 - DEBUG - Camera status : start.
2019-02-10 12:21:53,015 - DEBUG - Camera status : start.
2019-02-10 12:21:54,258 - DEBUG - Camera status : start.
2019-02-10 12:21:54,327 - DEBUG - Camera status : start.
2019-02-10 12:21:55,118 - DEBUG - Camera status : start.
2019-02-10 12:21:55,132 - DEBUG - Camera status : start.
2019-02-10 12:21:55,937 - DEBUG - Camera status : start.
2019-02-10 12:21:55,957 - DEBUG - Camera status : start.
2019-02-10 12:21:56,749 - DEBUG - Camera status : start.
2019-02-10 12:21:56,771 - DEBUG - Camera status : start.
2019-02-10 12:22:01,789 - DEBUG - Camera status : stop.
2019-02-10 12:22:01,796 - INFO - Send terminated order to <f_thread(Thread-2, started -1274022816)>
2019-02-10 12:22:01,806 - INFO - _stop_camera stopped after 278553 loops
